<?xml version="1.0" ?>
<!-- =================================================================================== -->
<!-- |    This document was autogenerated by xacro from spb_urdf.xacro               | -->
<!-- |    EDITING THIS FILE BY HAND IS NOT RECOMMENDED                                 | -->
<!-- =================================================================================== -->
<robot name="theimcbot_urdf">
  <!-- Specify some standard inertial calculations https://en.wikipedia.org/wiki/List_of_moments_of_inertia -->
  <!-- These make use of xacro's mathematical functionality -->
  <material name="Black">
    <color rgba="0.0 0.0 0.0 1.0"/>
  </material>
  <material name="Dark">
    <color rgba="0.3 0.3 0.3 1.0"/>
  </material>
  <material name="Light_black">
    <color rgba="0.4 0.4 0.4 1.0"/>
  </material>
  <material name="Blue">
    <color rgba="0.0 0.0 0.8 1.0"/>
  </material>
  <material name="Green">
    <color rgba="0.0 0.8 0.0 1.0"/>
  </material>
  <material name="Grey">
    <color rgba="0.5 0.5 0.5 1.0"/>
  </material>
  <material name="Orange">
    <color rgba="1.0 0.4235294117647059 0.0392156862745098 1.0"/>
  </material>
  <material name="Brown">
    <color rgba="0.8705882352941177 0.8117647058823529 0.7647058823529411 1.0"/>
  </material>
  <material name="Red">
    <color rgba="0.8 0.0 0.0 1.0"/>
  </material>
  <material name="White">
    <color rgba="1.0 1.0 1.0 1.0"/>
  </material>
  <material name="Cyan">
    <color rgba="0 1.0 1.0 1.0"/>
  </material>
  
  <!-- base_link -->
  <link name="base_link">
    <visual>
      <geometry>
        <box size="0.716 0.936 0.147"/>
      </geometry>
    </visual>
    <collision>
      <geometry>
        <box size="0.716 0.936 0.147"/>
      </geometry>
      <material name="Orange"/>
    </collision>
    <inertial>
      <origin rpy="0 0 0" xyz="0 0 0"/>
      <mass value="15.0"/>
      <inertia ixx="1.122" ixy="0.0" ixz="0.0" iyy="0.6678" iyz="0.0" izz="1.7359"/>
    </inertial>
  </link>

  <!-- base_footprint -->
  <link name="base_footprint"/>

  <!-- left wheel -->
  <link name="wheel_left_link">
    <visual>
      <origin rpy="1.5708 0 0" xyz="0 0 0"/>
      <geometry>
        <cylinder length="0.04" radius="0.08"/>
      </geometry>
      <material name="Cyan"/>
    </visual>
    <collision>
      <origin rpy="1.5708 0 0" xyz="0 0 0"/>
      <geometry>
        <cylinder length="0.04" radius="0.08"/>
      </geometry>
    </collision>
    <inertial>
      <origin rpy="0 0 0" xyz="0 0 0"/>
      <mass value="0.5"/>
      <inertia ixx="0.000866" ixy="0.0" ixz="0.0" iyy="0.0016" iyz="0.0" izz="0.000866"/>
    </inertial>
  </link>

  <!-- right wheel -->
  <link name="wheel_right_link">
    <visual>
      <origin rpy="1.5708 0 0" xyz="0 0 0"/>
      <geometry>
        <cylinder length="0.04" radius="0.08"/>
      </geometry>
      <material name="Cyan"/>
    </visual>
    <collision>
      <origin rpy="1.5708 0 0" xyz="0 0 0"/>
      <geometry>
        <cylinder length="0.04" radius="0.08"/>
      </geometry>
    </collision>
    <inertial>
      <origin rpy="0 0 0" xyz="0 0 0"/>
      <mass value="0.5"/>
      <inertia ixx="0.000866" ixy="0.0" ixz="0.0" iyy="0.0016" iyz="0.0" izz="0.000866"/>
    </inertial>
  </link>

  <!-- lidar -->
  <link name="laser_frame">
    <visual>
      <geometry>
        <cylinder length="0.02" radius="0.03"/>
      </geometry>
    </visual>
    <visual>
      <origin xyz="0 0 0.02"/>
      <geometry>
        <cylinder length="0.045" radius="0.03"/>
      </geometry>
      <material name="Blue"/>
    </visual>
    <collision>
      <geometry>
        <cylinder length="0.065" radius="0.03"/>
      </geometry>
    </collision>
    <inertial>
      <origin rpy="0 0 0" xyz="0 0 0"/>
      <mass value="0.2"/>
      <inertia ixx="0.00009006" ixy="0.0" ixz="0.0" iyy="0.00009006" iyz="0.0" izz="0.00009"/>
    </inertial>
  </link>

  <!-- imu -->
  <link name="imu_link">
    <visual>
      <geometry>
        <box size="0.05 0.1 0.01"/>
      </geometry>
      <material name="Brown"/>
    </visual>
    <collision>
      <geometry>
        <box size="0.05 0.1 0.01"/>
      </geometry>
    </collision>
    <inertial>
      <origin rpy="0 0 0" xyz="0 0 0"/>
      <mass value="0.02"/>
      <inertia ixx="0.00001683" ixy="0.0" ixz="0.0" iyy="0.00000433" iyz="0.0" izz="0.00002083"/>
    </inertial>
  </link>
  
  <!-- camera link -->
  <link name="camera_link">
    <visual>
      <origin xyz="0 0 0" rpy="0 0 0"/>
      <geometry>
        <box size="0.04 0.04 0.04"/>
      </geometry>
      <material name="Black"/>
    </visual>
    <collision>
      <origin xyz="0 0 0"/>
      <geometry>
        <box size="0.04 0.04 0.04"/>
      </geometry>
    </collision>
    <inertial>
      <origin xyz="0 0 0"/>
      <mass value="0.05"/>
      <inertia ixx="0.00001" ixy="0" ixz="0" iyy="0.00001" iyz="0" izz="0.00001"/>
    </inertial>
  </link>

  <!-- camera_rgb_frame (optical frame) -->
  <link name="camera_rgb_frame"/>

  <!-- camera mount joint -->
  <joint name="camera_joint" type="fixed">
    <parent link="base_link"/>
    <child link="camera_link"/>
    <origin xyz="0.19 0 0.10" rpy="0 0 0"/>
  </joint>

  <!-- optical frame joint -->
  <joint name="camera_rgb_joint" type="fixed">
    <parent link="camera_link"/>
    <child link="camera_rgb_frame"/>
    <origin xyz="0 0 0" rpy="0 1.57 0"/>
  </joint>

  <!-- joints -->
  <joint name="base_joint" type="fixed">
    <parent link="base_footprint"/>
    <child link="base_link"/>
    <origin rpy="0 0 0" xyz="0.0 0.0 0.33"/>
  </joint>

  <joint name="wheel_left_joint" type="continuous">
    <parent link="base_link"/>
    <child link="wheel_left_link"/>
    <origin rpy="0 0 0" xyz="0 0.45 -0.05"/>
    <axis xyz="0 1 0"/>
  </joint>

  <joint name="wheel_right_joint" type="continuous">
    <parent link="base_link"/>
    <child link="wheel_right_link"/>
    <origin rpy="0 0 0" xyz="0 -0.45 -0.05"/>
    <axis xyz="0 1 0"/>
  </joint>

  <joint name="lidar_joint" type="fixed">
    <parent link="base_link"/>
    <child link="laser_frame"/>
    <origin rpy="0 0 0" xyz="0.258 0 0.0725"/>
  </joint>

  <joint name="imu_joint" type="fixed">
    <parent link="base_link"/>
    <child link="imu_link"/>
    <origin rpy="0 0 0" xyz="0 0 0"/>
  </joint>

</robot>
